Workbook

Sheet Instructions
B2: TCO model - Africa Delivery, 5-year horizon (filled for 3 architecture options)
B4: Purpose | C4: Compare architecture options for ADR-001 by total cost of ownership incl. payroll and downtime risk.
B5: Sheets | C5: Assumptions (shared drivers) -> TCO-A / TCO-B / TCO-C (one copy of the template per option) -> Comparison.
B6: Legend | C6: Yellow cells = inputs. Everything else = formulas. Years 2-5 expand via the growth-index table.
B7: Deviations from template | C7: 1) CFO cap set to $5,000/mo (A6 p.1: $9k is the board figure incl. martech). 2) Downtime block uses a per-option SLO (cell D53 on each TCO sheet). 3) Loss per minute = $650 (GMV-at-risk, see Assumptions H19), not $12,000; sensitivity with $12k is on the Comparison sheet. 4) One-off items overwritten with explicit values in Years 2-5 (template rule).
B8: Fiscal year | C8: Year 1 = Oct-2026 .. Sep-2027 (launch 15-Oct-2026).
B9: Sources | C9: Artifact 5 (CTO letter), Artifact 6 (CFO letter), Artifact 2 (marketing brief), Task1/architecture-canvas.md, Task2/options-comparison.md.

Sheet Comparison
A2: Option comparison (formulas reference the three TCO sheets)
A3: Metric | B3: A Modular monolith | C3: B Service-based | D3: C Microservices (CTO) | E3: Comment
A4: Block 1 Cloud, 5 yrs | B4: ='TCO-A Modular Monolith'!J15 | C4: ='TCO-B Service-Based'!J15 | D4: ='TCO-C Microservices (CTO)'!J15
A5: Block 2 Licences & SaaS, 5 yrs | B5: ='TCO-A Modular Monolith'!J24 | C5: ='TCO-B Service-Based'!J24 | D5: ='TCO-C Microservices (CTO)'!J24
A6: Block 3 Transactions, 5 yrs | B6: ='TCO-A Modular Monolith'!J32 | C6: ='TCO-B Service-Based'!J32 | D6: ='TCO-C Microservices (CTO)'!J32 | E6: Pass-through, ~equal
A7: Block 4 Team, 5 yrs | B7: ='TCO-A Modular Monolith'!J40 | C7: ='TCO-B Service-Based'!J40 | D7: ='TCO-C Microservices (CTO)'!J40 | E7: Largest differentiator
A8: Block 5 One-off & compliance, 5 yrs | B8: ='TCO-A Modular Monolith'!J48 | C8: ='TCO-B Service-Based'!J48 | D8: ='TCO-C Microservices (CTO)'!J48
A9: TCO direct, 5 yrs | B9: ='TCO-A Modular Monolith'!J51 | C9: ='TCO-B Service-Based'!J51 | D9: ='TCO-C Microservices (CTO)'!J51
A10: Downtime loss, 5 yrs | B10: ='TCO-A Modular Monolith'!J53 | C10: ='TCO-B Service-Based'!J53 | D10: ='TCO-C Microservices (CTO)'!J53 | E10: At per-option SLO and $650/min
A11: TCO incl. downtime, 5 yrs | B11: ='TCO-A Modular Monolith'!J54 | C11: ='TCO-B Service-Based'!J54 | D11: ='TCO-C Microservices (CTO)'!J54
A12: NPV of costs, 5 yrs | B12: ='TCO-A Modular Monolith'!J56 | C12: ='TCO-B Service-Based'!J56 | D12: ='TCO-C Microservices (CTO)'!J56
A13: TCO per order, 5 yrs | B13: ='TCO-A Modular Monolith'!E65 | C13: ='TCO-B Service-Based'!E65 | D13: ='TCO-C Microservices (CTO)'!E65
A14: IT cost share of GMV | B14: ='TCO-A Modular Monolith'!E67 | C14: ='TCO-B Service-Based'!E67 | D14: ='TCO-C Microservices (CTO)'!E67
A15: Block 1, $/mo Year 1 | B15: ='TCO-A Modular Monolith'!E63 | C15: ='TCO-B Service-Based'!E63 | D15: ='TCO-C Microservices (CTO)'!E63
A16: Block 1+2, $/mo Year 1 (CFO scope) | B16: =('TCO-A Modular Monolith'!E15+'TCO-A Modular Monolith'!E24)/12 | C16: =('TCO-B Service-Based'!E15+'TCO-B Service-Based'!E24)/12 | D16: =('TCO-C Microservices (CTO)'!E15+'TCO-C Microservices (CTO)'!E24)/12 | E16: CFO counts compute, DB, CDN, monitoring, SaaS (A6 p.1)
A17: CFO $5k cap check | B17: =IF(('TCO-A Modular Monolith'!E15+'TCO-A Modular Monolith'!E24)/12<=Assumptions!$C$18,"OK","OVER") | C17: =IF(('TCO-B Service-Based'!E15+'TCO-B Service-Based'!E24)/12<=Assumptions!$C$18,"OK","OVER") | D17: =IF(('TCO-C Microservices (CTO)'!E15+'TCO-C Microservices (CTO)'!E24)/12<=Assumptions!$C$18,"OK","OVER")
A18: Engineers needed in Year 1 (FTE) | B18: 6 | C18: 8 | D18: 14 | E18: Hiring freeze: 6 contractors (A6 p.5)
A19: Earliest realistic go-live | B19: 15-Oct-2026 | C19: ~20-Nov-2026 | D19: ~Feb-2027 | E19: Task2/options-comparison.md
A21: Sensitivity: investor's $12,000/min (A1)
A22: Downtime loss/yr at $12k/min | B22: =(1-'TCO-A Modular Monolith'!$D$53)*525600*12000 | C22: =(1-'TCO-B Service-Based'!$D$53)*525600*12000 | D22: =(1-'TCO-C Microservices (CTO)'!$D$53)*525600*12000 | E22: 99.95% -> $3.15M/yr; 99.99% -> $0.63M/yr
A23: TCO incl. downtime at $12k/min, 5 yrs | B23: ='TCO-A Modular Monolith'!J51+5*(1-'TCO-A Modular Monolith'!$D$53)*525600*12000 | C23: ='TCO-B Service-Based'!J51+5*(1-'TCO-B Service-Based'!$D$53)*525600*12000 | D23: ='TCO-C Microservices (CTO)'!J51+5*(1-'TCO-C Microservices (CTO)'!$D$53)*525600*12000 | E23: At $12k/min the 4th nine pays back - but $12k/min = $6.3B GMV/yr
A24: Break-even loss/min for C vs A | D24: =('TCO-C Microservices (CTO)'!J51-'TCO-A Modular Monolith'!J51)/(5*525600*('TCO-C Microservices (CTO)'!D53-'TCO-A Modular Monolith'!D53)) | E24: Above this $/min C wins incl. downtime

Sheet Assumptions
B2: TCO model assumptions - Africa Delivery
B3: Only yellow cells are inputs.
B5: 1. Business drivers
B6: Metric | C6: Year 1 | D6: Year 2 | E6: Year 3 | F6: Year 4 | G6: Year 5 | H6: Comment / source
B7: Active users (end of year) | C7: 500000 | D7: 1500000 | E7: 3000000 | F7: 4500000 | G7: 6000000 | H7: Case goal: 1M+ registered in 12 mo (~50% active); 5 countries by Y1 end. Brief promise '1M buyers in month 1' rejected (Task1 C-06)
B8: Orders per year | C8: 600000 | D8: 3000000 | E8: 7500000 | F8: 13500000 | G8: 20000000 | H8: Pilot: 100 sellers / 5,000 SKU, ~20k orders/mo at launch -> ~100k/mo at month 12
B9: Average order value (AOV), $ | C9: 22 | D9: 23 | E9: 24 | F9: 25 | G9: 26 | H9: Low-price positioning (A7 'cheap'); below Jumia/Takealot basket
B10: GMV, $ per year (calc) | C10: =C8*C9 | D10: =D8*D9 | E10: =E8*E9 | F10: =F8*F9 | G10: =G8*G9 | H10: orders x AOV
B12: 2. Financial assumptions
B13: Parameter | C13: Value | H13: Comment / source
B14: Cost inflation, %/yr | C14: 0.08 | H14: USD-denominated costs
B15: Payroll growth, %/yr | C15: 0.12 | H15: Scarce senior engineers in target markets
B16: Discount rate, %/yr | C16: 0.2 | H16: Start-up risk premium
B17: Contingency, % | C17: 0.15 | H17: On direct costs
B18: CFO cap on cloud, $/mo | C18: 5000 | H18: Artifact 6 p.1: $5,000/mo hard ceiling for 6 months (the $9k figure is board deck incl. martech)
B19: Loss per minute of downtime, $ | C19: 650 | H19: GMV-at-risk: 5-yr avg GMV/min $425 x 1.5 peak weighting. Investor's $12,000 (A1, A7) implies $6.3B GMV/yr - see Comparison sensitivity
B20: Target SLO (global, unused - per-option SLO in TCO!D53) | C20: 0.9995 | H20: Kept for template compatibility
B21: Include downtime cost in TCO (1 = yes, 0 = no) | C21: 1 | H21: Scenario switch
B23: 3. Growth indices - calculated
B24: Driver | C24: Year 1 | D24: Year 2 | E24: Year 3 | F24: Year 4 | G24: Year 5 | H24: How
B25: fixed | C25: 1 | D25: 1 | E25: 1 | F25: 1 | G25: 1 | H25: Constant
B26: inflation | C26: 1 | D26: =C26*(1+$C$14) | E26: =D26*(1+$C$14) | F26: =E26*(1+$C$14) | G26: =F26*(1+$C$14) | H26: Year N = Year N-1 x (1 + inflation)
B27: payroll | C27: 1 | D27: =C27*(1+$C$15) | E27: =D27*(1+$C$15) | F27: =E27*(1+$C$15) | G27: =F27*(1+$C$15) | H27: Year N = Year N-1 x (1 + payroll growth)
B28: users | C28: =C7/$C$7 | D28: =D7/$C$7 | E28: =E7/$C$7 | F28: =F7/$C$7 | G28: =G7/$C$7 | H28: Proportional to active users
B29: orders | C29: =C8/$C$8 | D29: =D8/$C$8 | E29: =E8/$C$8 | F29: =F8/$C$8 | G29: =G8/$C$8 | H29: Proportional to orders
B30: GMV | C30: =C10/$C$10 | D30: =D10/$C$10 | E30: =E10/$C$10 | F30: =F10/$C$10 | G30: =G10/$C$10 | H30: Proportional to GMV
B32: The 'users' driver is a simplification: real cloud cost is sub-linear (economies of scale), so Years 3-5 infra is a conservative upper bound.

Sheet TCO-A Modular Monolith
B1: Option A - Modular monolith (Go) + managed PostgreSQL + Buy/Partner integrations
B2: 5-year TCO - Africa Delivery
B3: Inputs: 'Growth driver' and 'Base, $/yr (Year 1)'. Years 1-5 are calculated.
B5: Cost item | C5: Growth driver | D5: Base, $/yr (Year 1) | E5: Year 1 | F5: Year 2 | G5: Year 3 | H5: Year 4 | I5: Year 5 | J5: Total 5 yrs | K5: Share | L5: Comment / source
B6: BLOCK 1. Cloud infrastructure (OpEx)
B7: Compute: managed Kubernetes nodes | C7: users | D7: 10800 | E7: =IF($D7="","",$D7*INDEX(Assumptions!$C$25:$G$30,MATCH($C7,Assumptions!$B$25:$B$30,0),1)) | F7: =IF($D7="","",$D7*INDEX(Assumptions!$C$25:$G$30,MATCH($C7,Assumptions!$B$25:$B$30,0),2)) | G7: =IF($D7="","",$D7*INDEX(Assumptions!$C$25:$G$30,MATCH($C7,Assumptions!$B$25:$B$30,0),3)) | H7: =IF($D7="","",$D7*INDEX(Assumptions!$C$25:$G$30,MATCH($C7,Assumptions!$B$25:$B$30,0),4)) | I7: =IF($D7="","",$D7*INDEX(Assumptions!$C$25:$G$30,MATCH($C7,Assumptions!$B$25:$B$30,0),5)) | J7: =SUM(E7:I7) | L7: GKE africa-south1 (regional): 3 x n2d-standard-4 (sustained-use discount, no commitment); api x3 + worker + channels
B8: Managed PostgreSQL (Multi-AZ + read replica) | C8: users | D8: 8400 | E8: =IF($D8="","",$D8*INDEX(Assumptions!$C$25:$G$30,MATCH($C8,Assumptions!$B$25:$B$30,0),1)) | F8: =IF($D8="","",$D8*INDEX(Assumptions!$C$25:$G$30,MATCH($C8,Assumptions!$B$25:$B$30,0),2)) | G8: =IF($D8="","",$D8*INDEX(Assumptions!$C$25:$G$30,MATCH($C8,Assumptions!$B$25:$B$30,0),3)) | H8: =IF($D8="","",$D8*INDEX(Assumptions!$C$25:$G$30,MATCH($C8,Assumptions!$B$25:$B$30,0),4)) | I8: =IF($D8="","",$D8*INDEX(Assumptions!$C$25:$G$30,MATCH($C8,Assumptions!$B$25:$B$30,0),5)) | J8: =SUM(E8:I8) | L8: Cloud SQL PostgreSQL HA (4 vCPU/16 GB) + 1 read replica
B9: Object storage & backups | C9: users | D9: 1800 | E9: =IF($D9="","",$D9*INDEX(Assumptions!$C$25:$G$30,MATCH($C9,Assumptions!$B$25:$B$30,0),1)) | F9: =IF($D9="","",$D9*INDEX(Assumptions!$C$25:$G$30,MATCH($C9,Assumptions!$B$25:$B$30,0),2)) | G9: =IF($D9="","",$D9*INDEX(Assumptions!$C$25:$G$30,MATCH($C9,Assumptions!$B$25:$B$30,0),3)) | H9: =IF($D9="","",$D9*INDEX(Assumptions!$C$25:$G$30,MATCH($C9,Assumptions!$B$25:$B$30,0),4)) | I9: =IF($D9="","",$D9*INDEX(Assumptions!$C$25:$G$30,MATCH($C9,Assumptions!$B$25:$B$30,0),5)) | J9: =SUM(E9:I9) | L9: Cloud Storage: 5,000 SKU x 6 photos (WebP variants) + PITR backups
B10: CDN & egress | C10: users | D10: 4800 | E10: =IF($D10="","",$D10*INDEX(Assumptions!$C$25:$G$30,MATCH($C10,Assumptions!$B$25:$B$30,0),1)) | F10: =IF($D10="","",$D10*INDEX(Assumptions!$C$25:$G$30,MATCH($C10,Assumptions!$B$25:$B$30,0),2)) | G10: =IF($D10="","",$D10*INDEX(Assumptions!$C$25:$G$30,MATCH($C10,Assumptions!$B$25:$B$30,0),3)) | H10: =IF($D10="","",$D10*INDEX(Assumptions!$C$25:$G$30,MATCH($C10,Assumptions!$B$25:$B$30,0),4)) | I10: =IF($D10="","",$D10*INDEX(Assumptions!$C$25:$G$30,MATCH($C10,Assumptions!$B$25:$B$30,0),5)) | J10: =SUM(E10:I10) | L10: Cloudflare Pro + image resizing; PoPs in Lagos/Nairobi
B11: Queues / async jobs | C11: users | D11: 1200 | E11: =IF($D11="","",$D11*INDEX(Assumptions!$C$25:$G$30,MATCH($C11,Assumptions!$B$25:$B$30,0),1)) | F11: =IF($D11="","",$D11*INDEX(Assumptions!$C$25:$G$30,MATCH($C11,Assumptions!$B$25:$B$30,0),2)) | G11: =IF($D11="","",$D11*INDEX(Assumptions!$C$25:$G$30,MATCH($C11,Assumptions!$B$25:$B$30,0),3)) | H11: =IF($D11="","",$D11*INDEX(Assumptions!$C$25:$G$30,MATCH($C11,Assumptions!$B$25:$B$30,0),4)) | I11: =IF($D11="","",$D11*INDEX(Assumptions!$C$25:$G$30,MATCH($C11,Assumptions!$B$25:$B$30,0),5)) | J11: =SUM(E11:I11) | L11: Postgres outbox + Pub/Sub; no Kafka at MVP
B12: DR: pilot light in 2nd provider | C12: inflation | D12: 3000 | E12: =IF($D12="","",$D12*INDEX(Assumptions!$C$25:$G$30,MATCH($C12,Assumptions!$B$25:$B$30,0),1)) | F12: =IF($D12="","",$D12*INDEX(Assumptions!$C$25:$G$30,MATCH($C12,Assumptions!$B$25:$B$30,0),2)) | G12: =IF($D12="","",$D12*INDEX(Assumptions!$C$25:$G$30,MATCH($C12,Assumptions!$B$25:$B$30,0),3)) | H12: =IF($D12="","",$D12*INDEX(Assumptions!$C$25:$G$30,MATCH($C12,Assumptions!$B$25:$B$30,0),4)) | I12: =IF($D12="","",$D12*INDEX(Assumptions!$C$25:$G$30,MATCH($C12,Assumptions!$B$25:$B$30,0),5)) | J12: =SUM(E12:I12) | L12: Encrypted backups + IaC in AWS af-south-1 (Cape Town) - ADR-003
B13: Data residency: in-country PII vaults (NG, KE) | C13: inflation | D13: 8400 | E13: =IF($D13="","",$D13*INDEX(Assumptions!$C$25:$G$30,MATCH($C13,Assumptions!$B$25:$B$30,0),1)) | F13: =IF($D13="","",$D13*INDEX(Assumptions!$C$25:$G$30,MATCH($C13,Assumptions!$B$25:$B$30,0),2)) | G13: =IF($D13="","",$D13*INDEX(Assumptions!$C$25:$G$30,MATCH($C13,Assumptions!$B$25:$B$30,0),3)) | H13: =IF($D13="","",$D13*INDEX(Assumptions!$C$25:$G$30,MATCH($C13,Assumptions!$B$25:$B$30,0),4)) | I13: =IF($D13="","",$D13*INDEX(Assumptions!$C$25:$G$30,MATCH($C13,Assumptions!$B$25:$B$30,0),5)) | J13: =SUM(E13:I13) | L13: 2 small VMs + backup on local providers (Lagos, Nairobi) - ADR-003
B14: Cache: managed Redis (Multi-AZ) | C14: users | D14: 2400 | E14: =IF($D14="","",$D14*INDEX(Assumptions!$C$25:$G$30,MATCH($C14,Assumptions!$B$25:$B$30,0),1)) | F14: =IF($D14="","",$D14*INDEX(Assumptions!$C$25:$G$30,MATCH($C14,Assumptions!$B$25:$B$30,0),2)) | G14: =IF($D14="","",$D14*INDEX(Assumptions!$C$25:$G$30,MATCH($C14,Assumptions!$B$25:$B$30,0),3)) | H14: =IF($D14="","",$D14*INDEX(Assumptions!$C$25:$G$30,MATCH($C14,Assumptions!$B$25:$B$30,0),4)) | I14: =IF($D14="","",$D14*INDEX(Assumptions!$C$25:$G$30,MATCH($C14,Assumptions!$B$25:$B$30,0),5)) | J14: =SUM(E14:I14) | L14: Memorystore Redis Standard (HA) 2 GB - ADR-002
B15: Block total | E15: =SUM(E7:E14) | F15: =SUM(F7:F14) | G15: =SUM(G7:G14) | H15: =SUM(H7:H14) | I15: =SUM(I7:I14) | J15: =SUM(J7:J14) | K15: =IFERROR(J15/$J$51,0)
B17: BLOCK 2. Licences, SaaS & tools
B18: Observability (metrics, logs, traces) | C18: users | D18: 2400 | E18: =IF($D18="","",$D18*INDEX(Assumptions!$C$25:$G$30,MATCH($C18,Assumptions!$B$25:$B$30,0),1)) | F18: =IF($D18="","",$D18*INDEX(Assumptions!$C$25:$G$30,MATCH($C18,Assumptions!$B$25:$B$30,0),2)) | G18: =IF($D18="","",$D18*INDEX(Assumptions!$C$25:$G$30,MATCH($C18,Assumptions!$B$25:$B$30,0),3)) | H18: =IF($D18="","",$D18*INDEX(Assumptions!$C$25:$G$30,MATCH($C18,Assumptions!$B$25:$B$30,0),4)) | I18: =IF($D18="","",$D18*INDEX(Assumptions!$C$25:$G$30,MATCH($C18,Assumptions!$B$25:$B$30,0),5)) | J18: =SUM(E18:I18) | L18: Grafana Cloud Pro usage-based; OpenTelemetry SDK
B19: CI/CD, repo, artifacts | C19: inflation | D19: 1200 | E19: =IF($D19="","",$D19*INDEX(Assumptions!$C$25:$G$30,MATCH($C19,Assumptions!$B$25:$B$30,0),1)) | F19: =IF($D19="","",$D19*INDEX(Assumptions!$C$25:$G$30,MATCH($C19,Assumptions!$B$25:$B$30,0),2)) | G19: =IF($D19="","",$D19*INDEX(Assumptions!$C$25:$G$30,MATCH($C19,Assumptions!$B$25:$B$30,0),3)) | H19: =IF($D19="","",$D19*INDEX(Assumptions!$C$25:$G$30,MATCH($C19,Assumptions!$B$25:$B$30,0),4)) | I19: =IF($D19="","",$D19*INDEX(Assumptions!$C$25:$G$30,MATCH($C19,Assumptions!$B$25:$B$30,0),5)) | J19: =SUM(E19:I19) | L19: GitHub Team x10 + Actions; ArgoCD self-hosted
B20: Security: WAF, secrets, error tracking | C20: users | D20: 1800 | E20: =IF($D20="","",$D20*INDEX(Assumptions!$C$25:$G$30,MATCH($C20,Assumptions!$B$25:$B$30,0),1)) | F20: =IF($D20="","",$D20*INDEX(Assumptions!$C$25:$G$30,MATCH($C20,Assumptions!$B$25:$B$30,0),2)) | G20: =IF($D20="","",$D20*INDEX(Assumptions!$C$25:$G$30,MATCH($C20,Assumptions!$B$25:$B$30,0),3)) | H20: =IF($D20="","",$D20*INDEX(Assumptions!$C$25:$G$30,MATCH($C20,Assumptions!$B$25:$B$30,0),4)) | I20: =IF($D20="","",$D20*INDEX(Assumptions!$C$25:$G$30,MATCH($C20,Assumptions!$B$25:$B$30,0),5)) | J20: =SUM(E20:I20) | L20: Cloudflare WAF, Cloud KMS/Secret Manager, Sentry Team
B21: WhatsApp Business API (BSP subscription) | C21: inflation | D21: 1200 | E21: =IF($D21="","",$D21*INDEX(Assumptions!$C$25:$G$30,MATCH($C21,Assumptions!$B$25:$B$30,0),1)) | F21: =IF($D21="","",$D21*INDEX(Assumptions!$C$25:$G$30,MATCH($C21,Assumptions!$B$25:$B$30,0),2)) | G21: =IF($D21="","",$D21*INDEX(Assumptions!$C$25:$G$30,MATCH($C21,Assumptions!$B$25:$B$30,0),3)) | H21: =IF($D21="","",$D21*INDEX(Assumptions!$C$25:$G$30,MATCH($C21,Assumptions!$B$25:$B$30,0),4)) | I21: =IF($D21="","",$D21*INDEX(Assumptions!$C$25:$G$30,MATCH($C21,Assumptions!$B$25:$B$30,0),5)) | J21: =SUM(E21:I21) | L21: 2 numbers (NG, KE)
B22: Other SaaS | C22: inflation | D22: 1800 | E22: =IF($D22="","",$D22*INDEX(Assumptions!$C$25:$G$30,MATCH($C22,Assumptions!$B$25:$B$30,0),1)) | F22: =IF($D22="","",$D22*INDEX(Assumptions!$C$25:$G$30,MATCH($C22,Assumptions!$B$25:$B$30,0),2)) | G22: =IF($D22="","",$D22*INDEX(Assumptions!$C$25:$G$30,MATCH($C22,Assumptions!$B$25:$B$30,0),3)) | H22: =IF($D22="","",$D22*INDEX(Assumptions!$C$25:$G$30,MATCH($C22,Assumptions!$B$25:$B$30,0),4)) | I22: =IF($D22="","",$D22*INDEX(Assumptions!$C$25:$G$30,MATCH($C22,Assumptions!$B$25:$B$30,0),5)) | J22: =SUM(E22:I22) | L22: Tracker, Figma; Metabase self-hosted
C23: fixed | E23: =IF($D23="","",$D23*INDEX(Assumptions!$C$25:$G$30,MATCH($C23,Assumptions!$B$25:$B$30,0),1)) | F23: =IF($D23="","",$D23*INDEX(Assumptions!$C$25:$G$30,MATCH($C23,Assumptions!$B$25:$B$30,0),2)) | G23: =IF($D23="","",$D23*INDEX(Assumptions!$C$25:$G$30,MATCH($C23,Assumptions!$B$25:$B$30,0),3)) | H23: =IF($D23="","",$D23*INDEX(Assumptions!$C$25:$G$30,MATCH($C23,Assumptions!$B$25:$B$30,0),4)) | I23: =IF($D23="","",$D23*INDEX(Assumptions!$C$25:$G$30,MATCH($C23,Assumptions!$B$25:$B$30,0),5)) | J23: =SUM(E23:I23)
B24: Block total | E24: =SUM(E18:E23) | F24: =SUM(F18:F23) | G24: =SUM(G18:G23) | H24: =SUM(H18:H23) | I24: =SUM(I18:I23) | J24: =SUM(J18:J23) | K24: =IFERROR(J24/$J$51,0)
B26: BLOCK 3. Transaction costs (Buy / Partner)
B27: Payment provider fees (all-in, incl. payouts & FX) | C27: GMV | D27: 250800 | E27: =IF($D27="","",$D27*INDEX(Assumptions!$C$25:$G$30,MATCH($C27,Assumptions!$B$25:$B$30,0),1)) | F27: =IF($D27="","",$D27*INDEX(Assumptions!$C$25:$G$30,MATCH($C27,Assumptions!$B$25:$B$30,0),2)) | G27: =IF($D27="","",$D27*INDEX(Assumptions!$C$25:$G$30,MATCH($C27,Assumptions!$B$25:$B$30,0),3)) | H27: =IF($D27="","",$D27*INDEX(Assumptions!$C$25:$G$30,MATCH($C27,Assumptions!$B$25:$B$30,0),4)) | I27: =IF($D27="","",$D27*INDEX(Assumptions!$C$25:$G$30,MATCH($C27,Assumptions!$B$25:$B$30,0),5)) | J27: =SUM(E27:I27) | L27: 1.9% blended of Y1 GMV $13.2M - see Task5/adr-004 (cap 2.5%, A6 p.6)
B28: SMS notifications | C28: orders | D28: 36000 | E28: =IF($D28="","",$D28*INDEX(Assumptions!$C$25:$G$30,MATCH($C28,Assumptions!$B$25:$B$30,0),1)) | F28: =IF($D28="","",$D28*INDEX(Assumptions!$C$25:$G$30,MATCH($C28,Assumptions!$B$25:$B$30,0),2)) | G28: =IF($D28="","",$D28*INDEX(Assumptions!$C$25:$G$30,MATCH($C28,Assumptions!$B$25:$B$30,0),3)) | H28: =IF($D28="","",$D28*INDEX(Assumptions!$C$25:$G$30,MATCH($C28,Assumptions!$B$25:$B$30,0),4)) | I28: =IF($D28="","",$D28*INDEX(Assumptions!$C$25:$G$30,MATCH($C28,Assumptions!$B$25:$B$30,0),5)) | J28: =SUM(E28:I28) | L28: 3 SMS/order x $0.02 (Africa's Talking NG/KE)
B29: WhatsApp messages (utility templates) | C29: orders | D29: 6000 | E29: =IF($D29="","",$D29*INDEX(Assumptions!$C$25:$G$30,MATCH($C29,Assumptions!$B$25:$B$30,0),1)) | F29: =IF($D29="","",$D29*INDEX(Assumptions!$C$25:$G$30,MATCH($C29,Assumptions!$B$25:$B$30,0),2)) | G29: =IF($D29="","",$D29*INDEX(Assumptions!$C$25:$G$30,MATCH($C29,Assumptions!$B$25:$B$30,0),3)) | H29: =IF($D29="","",$D29*INDEX(Assumptions!$C$25:$G$30,MATCH($C29,Assumptions!$B$25:$B$30,0),4)) | I29: =IF($D29="","",$D29*INDEX(Assumptions!$C$25:$G$30,MATCH($C29,Assumptions!$B$25:$B$30,0),5)) | J29: =SUM(E29:I29) | L29: ~$0.01/order seller+buyer utility msgs
B30: Logistics: partner API fees + delivery subsidy | C30: orders | D30: 90000 | E30: =IF($D30="","",$D30*INDEX(Assumptions!$C$25:$G$30,MATCH($C30,Assumptions!$B$25:$B$30,0),1)) | F30: =IF($D30="","",$D30*INDEX(Assumptions!$C$25:$G$30,MATCH($C30,Assumptions!$B$25:$B$30,0),2)) | G30: =IF($D30="","",$D30*INDEX(Assumptions!$C$25:$G$30,MATCH($C30,Assumptions!$B$25:$B$30,0),3)) | H30: =IF($D30="","",$D30*INDEX(Assumptions!$C$25:$G$30,MATCH($C30,Assumptions!$B$25:$B$30,0),4)) | I30: =IF($D30="","",$D30*INDEX(Assumptions!$C$25:$G$30,MATCH($C30,Assumptions!$B$25:$B$30,0),5)) | J30: =SUM(E30:I30) | L30: $0.15/order platform-paid on top of buyer delivery fee (Sendbox NG, Sendy KE)
B31: USSD sessions + short codes (NG, KE) | C31: orders | D31: 12000 | E31: =IF($D31="","",$D31*INDEX(Assumptions!$C$25:$G$30,MATCH($C31,Assumptions!$B$25:$B$30,0),1)) | F31: =IF($D31="","",$D31*INDEX(Assumptions!$C$25:$G$30,MATCH($C31,Assumptions!$B$25:$B$30,0),2)) | G31: =IF($D31="","",$D31*INDEX(Assumptions!$C$25:$G$30,MATCH($C31,Assumptions!$B$25:$B$30,0),3)) | H31: =IF($D31="","",$D31*INDEX(Assumptions!$C$25:$G$30,MATCH($C31,Assumptions!$B$25:$B$30,0),4)) | I31: =IF($D31="","",$D31*INDEX(Assumptions!$C$25:$G$30,MATCH($C31,Assumptions!$B$25:$B$30,0),5)) | J31: =SUM(E31:I31) | L31: Africa's Talking USSD aggregator
B32: Block total | E32: =SUM(E27:E31) | F32: =SUM(F27:F31) | G32: =SUM(G27:G31) | H32: =SUM(H27:H31) | I32: =SUM(I27:I31) | J32: =SUM(J27:J31) | K32: =IFERROR(J32/$J$51,0)
B34: BLOCK 4. Team (payroll)
B35: Development (FTE x annual rate) | C35: payroll | D35: 300000 | E35: =IF($D35="","",$D35*INDEX(Assumptions!$C$25:$G$30,MATCH($C35,Assumptions!$B$25:$B$30,0),1)) | F35: =IF($D35="","",$D35*INDEX(Assumptions!$C$25:$G$30,MATCH($C35,Assumptions!$B$25:$B$30,0),2)) | G35: =IF($D35="","",$D35*INDEX(Assumptions!$C$25:$G$30,MATCH($C35,Assumptions!$B$25:$B$30,0),3)) | H35: =IF($D35="","",$D35*INDEX(Assumptions!$C$25:$G$30,MATCH($C35,Assumptions!$B$25:$B$30,0),4)) | I35: =IF($D35="","",$D35*INDEX(Assumptions!$C$25:$G$30,MATCH($C35,Assumptions!$B$25:$B$30,0),5)) | J35: =SUM(E35:I35) | L35: 5 contractors x $60k: Go x2, Flutter x1, full-stack x1, integrations/USSD x1
B36: DevOps / SRE | C36: payroll | D36: 72000 | E36: =IF($D36="","",$D36*INDEX(Assumptions!$C$25:$G$30,MATCH($C36,Assumptions!$B$25:$B$30,0),1)) | F36: =IF($D36="","",$D36*INDEX(Assumptions!$C$25:$G$30,MATCH($C36,Assumptions!$B$25:$B$30,0),2)) | G36: =IF($D36="","",$D36*INDEX(Assumptions!$C$25:$G$30,MATCH($C36,Assumptions!$B$25:$B$30,0),3)) | H36: =IF($D36="","",$D36*INDEX(Assumptions!$C$25:$G$30,MATCH($C36,Assumptions!$B$25:$B$30,0),4)) | I36: =IF($D36="","",$D36*INDEX(Assumptions!$C$25:$G$30,MATCH($C36,Assumptions!$B$25:$B$30,0),5)) | J36: =SUM(E36:I36) | L36: 1 platform/SRE contractor
B37: On-call 24/7 (follow-the-sun stipend) | C37: payroll | D37: 18000 | E37: =IF($D37="","",$D37*INDEX(Assumptions!$C$25:$G$30,MATCH($C37,Assumptions!$B$25:$B$30,0),1)) | F37: =IF($D37="","",$D37*INDEX(Assumptions!$C$25:$G$30,MATCH($C37,Assumptions!$B$25:$B$30,0),2)) | G37: =IF($D37="","",$D37*INDEX(Assumptions!$C$25:$G$30,MATCH($C37,Assumptions!$B$25:$B$30,0),3)) | H37: =IF($D37="","",$D37*INDEX(Assumptions!$C$25:$G$30,MATCH($C37,Assumptions!$B$25:$B$30,0),4)) | I37: =IF($D37="","",$D37*INDEX(Assumptions!$C$25:$G$30,MATCH($C37,Assumptions!$B$25:$B$30,0),5)) | J37: =SUM(E37:I37) | L37: $1.5k/mo across 6 contractors in 3 time zones
B38: Architecture & management | C38: payroll | D38: 200000 | E38: =IF($D38="","",$D38*INDEX(Assumptions!$C$25:$G$30,MATCH($C38,Assumptions!$B$25:$B$30,0),1)) | F38: =IF($D38="","",$D38*INDEX(Assumptions!$C$25:$G$30,MATCH($C38,Assumptions!$B$25:$B$30,0),2)) | G38: =IF($D38="","",$D38*INDEX(Assumptions!$C$25:$G$30,MATCH($C38,Assumptions!$B$25:$B$30,0),3)) | H38: =IF($D38="","",$D38*INDEX(Assumptions!$C$25:$G$30,MATCH($C38,Assumptions!$B$25:$B$30,0),4)) | I38: =IF($D38="","",$D38*INDEX(Assumptions!$C$25:$G$30,MATCH($C38,Assumptions!$B$25:$B$30,0),5)) | J38: =SUM(E38:I38) | L38: Solution Architect (deputy CTO) + PM from Q1-2027 + 50% CTO
B39: Team growth from Y2 (+4 engineers) | C39: payroll | D39: 240000 | E39: 0 | F39: =IF($D39="","",$D39*INDEX(Assumptions!$C$25:$G$30,MATCH($C39,Assumptions!$B$25:$B$30,0),2)) | G39: =IF($D39="","",$D39*INDEX(Assumptions!$C$25:$G$30,MATCH($C39,Assumptions!$B$25:$B$30,0),3)) | H39: =IF($D39="","",$D39*INDEX(Assumptions!$C$25:$G$30,MATCH($C39,Assumptions!$B$25:$B$30,0),4)) | I39: =IF($D39="","",$D39*INDEX(Assumptions!$C$25:$G$30,MATCH($C39,Assumptions!$B$25:$B$30,0),5)) | J39: =SUM(E39:I39) | L39: Hiring freeze to Dec-2026; Y1 = 0 (overridden)
B40: Block total | E40: =SUM(E35:E39) | F40: =SUM(F35:F39) | G40: =SUM(G35:G39) | H40: =SUM(H35:H39) | I40: =SUM(I35:I39) | J40: =SUM(J35:J39) | K40: =IFERROR(J40/$J$51,0)
B42: BLOCK 5. One-off & compliance
B43: Legal & compliance (NDPR/NDPA, POPIA, KE DPA) | C43: fixed | D43: 30000 | E43: =IF($D43="","",$D43*INDEX(Assumptions!$C$25:$G$30,MATCH($C43,Assumptions!$B$25:$B$30,0),1)) | F43: 15000 | G43: 15000 | H43: 15000 | I43: 15000 | J43: =SUM(E43:I43) | L43: Y1: DPIA, NDPC/ODPC registration, outsourced DPO; Y2+: annual NDPC audit filing
B44: Penetration test & security audit | C44: inflation | D44: 12000 | E44: =IF($D44="","",$D44*INDEX(Assumptions!$C$25:$G$30,MATCH($C44,Assumptions!$B$25:$B$30,0),1)) | F44: =IF($D44="","",$D44*INDEX(Assumptions!$C$25:$G$30,MATCH($C44,Assumptions!$B$25:$B$30,0),2)) | G44: =IF($D44="","",$D44*INDEX(Assumptions!$C$25:$G$30,MATCH($C44,Assumptions!$B$25:$B$30,0),3)) | H44: =IF($D44="","",$D44*INDEX(Assumptions!$C$25:$G$30,MATCH($C44,Assumptions!$B$25:$B$30,0),4)) | I44: =IF($D44="","",$D44*INDEX(Assumptions!$C$25:$G$30,MATCH($C44,Assumptions!$B$25:$B$30,0),5)) | J44: =SUM(E44:I44) | L44: Annual, before peak season
B45: Launch integrations & certification | C45: fixed | D45: 10000 | E45: =IF($D45="","",$D45*INDEX(Assumptions!$C$25:$G$30,MATCH($C45,Assumptions!$B$25:$B$30,0),1)) | F45: 0 | G45: 0 | H45: 0 | I45: 0 | J45: =SUM(E45:I45) | L45: PSP/logistics prod certification, catalog import tooling; one-off
...

Sheet TCO-B Service-Based
B1: Option B - Service-based architecture (6 coarse services, managed broker)
B2: 5-year TCO - Africa Delivery
B3: Inputs: 'Growth driver' and 'Base, $/yr (Year 1)'. Years 1-5 are calculated.
B5: Cost item | C5: Growth driver | D5: Base, $/yr (Year 1) | E5: Year 1 | F5: Year 2 | G5: Year 3 | H5: Year 4 | I5: Year 5 | J5: Total 5 yrs | K5: Share | L5: Comment / source
B6: BLOCK 1. Cloud infrastructure (OpEx)
B7: Compute: managed Kubernetes nodes | C7: users | D7: 18000 | E7: =IF($D7="","",$D7*INDEX(Assumptions!$C$25:$G$30,MATCH($C7,Assumptions!$B$25:$B$30,0),1)) | F7: =IF($D7="","",$D7*INDEX(Assumptions!$C$25:$G$30,MATCH($C7,Assumptions!$B$25:$B$30,0),2)) | G7: =IF($D7="","",$D7*INDEX(Assumptions!$C$25:$G$30,MATCH($C7,Assumptions!$B$25:$B$30,0),3)) | H7: =IF($D7="","",$D7*INDEX(Assumptions!$C$25:$G$30,MATCH($C7,Assumptions!$B$25:$B$30,0),4)) | I7: =IF($D7="","",$D7*INDEX(Assumptions!$C$25:$G$30,MATCH($C7,Assumptions!$B$25:$B$30,0),5)) | J7: =SUM(E7:I7) | L7: GKE: 5 nodes, 6 services x 2 replicas
B8: Managed PostgreSQL (2 clusters, Multi-AZ) | C8: users | D8: 14400 | E8: =IF($D8="","",$D8*INDEX(Assumptions!$C$25:$G$30,MATCH($C8,Assumptions!$B$25:$B$30,0),1)) | F8: =IF($D8="","",$D8*INDEX(Assumptions!$C$25:$G$30,MATCH($C8,Assumptions!$B$25:$B$30,0),2)) | G8: =IF($D8="","",$D8*INDEX(Assumptions!$C$25:$G$30,MATCH($C8,Assumptions!$B$25:$B$30,0),3)) | H8: =IF($D8="","",$D8*INDEX(Assumptions!$C$25:$G$30,MATCH($C8,Assumptions!$B$25:$B$30,0),4)) | I8: =IF($D8="","",$D8*INDEX(Assumptions!$C$25:$G$30,MATCH($C8,Assumptions!$B$25:$B$30,0),5)) | J8: =SUM(E8:I8) | L8: Transactional + catalog databases
B9: Object storage & backups | C9: users | D9: 2400 | E9: =IF($D9="","",$D9*INDEX(Assumptions!$C$25:$G$30,MATCH($C9,Assumptions!$B$25:$B$30,0),1)) | F9: =IF($D9="","",$D9*INDEX(Assumptions!$C$25:$G$30,MATCH($C9,Assumptions!$B$25:$B$30,0),2)) | G9: =IF($D9="","",$D9*INDEX(Assumptions!$C$25:$G$30,MATCH($C9,Assumptions!$B$25:$B$30,0),3)) | H9: =IF($D9="","",$D9*INDEX(Assumptions!$C$25:$G$30,MATCH($C9,Assumptions!$B$25:$B$30,0),4)) | I9: =IF($D9="","",$D9*INDEX(Assumptions!$C$25:$G$30,MATCH($C9,Assumptions!$B$25:$B$30,0),5)) | J9: =SUM(E9:I9) | L9: S3 + backups per service
B10: CDN & egress | C10: users | D10: 4800 | E10: =IF($D10="","",$D10*INDEX(Assumptions!$C$25:$G$30,MATCH($C10,Assumptions!$B$25:$B$30,0),1)) | F10: =IF($D10="","",$D10*INDEX(Assumptions!$C$25:$G$30,MATCH($C10,Assumptions!$B$25:$B$30,0),2)) | G10: =IF($D10="","",$D10*INDEX(Assumptions!$C$25:$G$30,MATCH($C10,Assumptions!$B$25:$B$30,0),3)) | H10: =IF($D10="","",$D10*INDEX(Assumptions!$C$25:$G$30,MATCH($C10,Assumptions!$B$25:$B$30,0),4)) | I10: =IF($D10="","",$D10*INDEX(Assumptions!$C$25:$G$30,MATCH($C10,Assumptions!$B$25:$B$30,0),5)) | J10: =SUM(E10:I10) | L10: Cloudflare Pro
B11: Managed message broker | C11: users | D11: 6000 | E11: =IF($D11="","",$D11*INDEX(Assumptions!$C$25:$G$30,MATCH($C11,Assumptions!$B$25:$B$30,0),1)) | F11: =IF($D11="","",$D11*INDEX(Assumptions!$C$25:$G$30,MATCH($C11,Assumptions!$B$25:$B$30,0),2)) | G11: =IF($D11="","",$D11*INDEX(Assumptions!$C$25:$G$30,MATCH($C11,Assumptions!$B$25:$B$30,0),3)) | H11: =IF($D11="","",$D11*INDEX(Assumptions!$C$25:$G$30,MATCH($C11,Assumptions!$B$25:$B$30,0),4)) | I11: =IF($D11="","",$D11*INDEX(Assumptions!$C$25:$G$30,MATCH($C11,Assumptions!$B$25:$B$30,0),5)) | J11: =SUM(E11:I11) | L11: Managed RabbitMQ (CloudAMQP) / Pub/Sub
B12: DR: pilot light in 2nd provider | C12: inflation | D12: 4800 | E12: =IF($D12="","",$D12*INDEX(Assumptions!$C$25:$G$30,MATCH($C12,Assumptions!$B$25:$B$30,0),1)) | F12: =IF($D12="","",$D12*INDEX(Assumptions!$C$25:$G$30,MATCH($C12,Assumptions!$B$25:$B$30,0),2)) | G12: =IF($D12="","",$D12*INDEX(Assumptions!$C$25:$G$30,MATCH($C12,Assumptions!$B$25:$B$30,0),3)) | H12: =IF($D12="","",$D12*INDEX(Assumptions!$C$25:$G$30,MATCH($C12,Assumptions!$B$25:$B$30,0),4)) | I12: =IF($D12="","",$D12*INDEX(Assumptions!$C$25:$G$30,MATCH($C12,Assumptions!$B$25:$B$30,0),5)) | J12: =SUM(E12:I12) | L12: Backups + IaC, 2 DBs
B13: Data residency: in-country PII vaults (NG, KE) | C13: inflation | D13: 8400 | E13: =IF($D13="","",$D13*INDEX(Assumptions!$C$25:$G$30,MATCH($C13,Assumptions!$B$25:$B$30,0),1)) | F13: =IF($D13="","",$D13*INDEX(Assumptions!$C$25:$G$30,MATCH($C13,Assumptions!$B$25:$B$30,0),2)) | G13: =IF($D13="","",$D13*INDEX(Assumptions!$C$25:$G$30,MATCH($C13,Assumptions!$B$25:$B$30,0),3)) | H13: =IF($D13="","",$D13*INDEX(Assumptions!$C$25:$G$30,MATCH($C13,Assumptions!$B$25:$B$30,0),4)) | I13: =IF($D13="","",$D13*INDEX(Assumptions!$C$25:$G$30,MATCH($C13,Assumptions!$B$25:$B$30,0),5)) | J13: =SUM(E13:I13) | L13: Same as A
B14: Cache: managed Redis (Multi-AZ) | C14: users | D14: 2400 | E14: =IF($D14="","",$D14*INDEX(Assumptions!$C$25:$G$30,MATCH($C14,Assumptions!$B$25:$B$30,0),1)) | F14: =IF($D14="","",$D14*INDEX(Assumptions!$C$25:$G$30,MATCH($C14,Assumptions!$B$25:$B$30,0),2)) | G14: =IF($D14="","",$D14*INDEX(Assumptions!$C$25:$G$30,MATCH($C14,Assumptions!$B$25:$B$30,0),3)) | H14: =IF($D14="","",$D14*INDEX(Assumptions!$C$25:$G$30,MATCH($C14,Assumptions!$B$25:$B$30,0),4)) | I14: =IF($D14="","",$D14*INDEX(Assumptions!$C$25:$G$30,MATCH($C14,Assumptions!$B$25:$B$30,0),5)) | J14: =SUM(E14:I14) | L14: Memorystore
B15: Block total | E15: =SUM(E7:E14) | F15: =SUM(F7:F14) | G15: =SUM(G7:G14) | H15: =SUM(H7:H14) | I15: =SUM(I7:I14) | J15: =SUM(J7:J14) | K15: =IFERROR(J15/$J$51,0)
B17: BLOCK 2. Licences, SaaS & tools
B18: Observability (metrics, logs, traces) | C18: users | D18: 4800 | E18: =IF($D18="","",$D18*INDEX(Assumptions!$C$25:$G$30,MATCH($C18,Assumptions!$B$25:$B$30,0),1)) | F18: =IF($D18="","",$D18*INDEX(Assumptions!$C$25:$G$30,MATCH($C18,Assumptions!$B$25:$B$30,0),2)) | G18: =IF($D18="","",$D18*INDEX(Assumptions!$C$25:$G$30,MATCH($C18,Assumptions!$B$25:$B$30,0),3)) | H18: =IF($D18="","",$D18*INDEX(Assumptions!$C$25:$G$30,MATCH($C18,Assumptions!$B$25:$B$30,0),4)) | I18: =IF($D18="","",$D18*INDEX(Assumptions!$C$25:$G$30,MATCH($C18,Assumptions!$B$25:$B$30,0),5)) | J18: =SUM(E18:I18) | L18: Grafana Cloud, 6 services, more traces
B19: CI/CD, repo, artifacts | C19: inflation | D19: 2400 | E19: =IF($D19="","",$D19*INDEX(Assumptions!$C$25:$G$30,MATCH($C19,Assumptions!$B$25:$B$30,0),1)) | F19: =IF($D19="","",$D19*INDEX(Assumptions!$C$25:$G$30,MATCH($C19,Assumptions!$B$25:$B$30,0),2)) | G19: =IF($D19="","",$D19*INDEX(Assumptions!$C$25:$G$30,MATCH($C19,Assumptions!$B$25:$B$30,0),3)) | H19: =IF($D19="","",$D19*INDEX(Assumptions!$C$25:$G$30,MATCH($C19,Assumptions!$B$25:$B$30,0),4)) | I19: =IF($D19="","",$D19*INDEX(Assumptions!$C$25:$G$30,MATCH($C19,Assumptions!$B$25:$B$30,0),5)) | J19: =SUM(E19:I19) | L19: 6 pipelines
B20: Security: WAF, secrets, error tracking | C20: users | D20: 2400 | E20: =IF($D20="","",$D20*INDEX(Assumptions!$C$25:$G$30,MATCH($C20,Assumptions!$B$25:$B$30,0),1)) | F20: =IF($D20="","",$D20*INDEX(Assumptions!$C$25:$G$30,MATCH($C20,Assumptions!$B$25:$B$30,0),2)) | G20: =IF($D20="","",$D20*INDEX(Assumptions!$C$25:$G$30,MATCH($C20,Assumptions!$B$25:$B$30,0),3)) | H20: =IF($D20="","",$D20*INDEX(Assumptions!$C$25:$G$30,MATCH($C20,Assumptions!$B$25:$B$30,0),4)) | I20: =IF($D20="","",$D20*INDEX(Assumptions!$C$25:$G$30,MATCH($C20,Assumptions!$B$25:$B$30,0),5)) | J20: =SUM(E20:I20)
B21: WhatsApp Business API (BSP subscription) | C21: inflation | D21: 1200 | E21: =IF($D21="","",$D21*INDEX(Assumptions!$C$25:$G$30,MATCH($C21,Assumptions!$B$25:$B$30,0),1)) | F21: =IF($D21="","",$D21*INDEX(Assumptions!$C$25:$G$30,MATCH($C21,Assumptions!$B$25:$B$30,0),2)) | G21: =IF($D21="","",$D21*INDEX(Assumptions!$C$25:$G$30,MATCH($C21,Assumptions!$B$25:$B$30,0),3)) | H21: =IF($D21="","",$D21*INDEX(Assumptions!$C$25:$G$30,MATCH($C21,Assumptions!$B$25:$B$30,0),4)) | I21: =IF($D21="","",$D21*INDEX(Assumptions!$C$25:$G$30,MATCH($C21,Assumptions!$B$25:$B$30,0),5)) | J21: =SUM(E21:I21)
B22: Other SaaS | C22: inflation | D22: 1800 | E22: =IF($D22="","",$D22*INDEX(Assumptions!$C$25:$G$30,MATCH($C22,Assumptions!$B$25:$B$30,0),1)) | F22: =IF($D22="","",$D22*INDEX(Assumptions!$C$25:$G$30,MATCH($C22,Assumptions!$B$25:$B$30,0),2)) | G22: =IF($D22="","",$D22*INDEX(Assumptions!$C$25:$G$30,MATCH($C22,Assumptions!$B$25:$B$30,0),3)) | H22: =IF($D22="","",$D22*INDEX(Assumptions!$C$25:$G$30,MATCH($C22,Assumptions!$B$25:$B$30,0),4)) | I22: =IF($D22="","",$D22*INDEX(Assumptions!$C$25:$G$30,MATCH($C22,Assumptions!$B$25:$B$30,0),5)) | J22: =SUM(E22:I22)
C23: fixed | E23: =IF($D23="","",$D23*INDEX(Assumptions!$C$25:$G$30,MATCH($C23,Assumptions!$B$25:$B$30,0),1)) | F23: =IF($D23="","",$D23*INDEX(Assumptions!$C$25:$G$30,MATCH($C23,Assumptions!$B$25:$B$30,0),2)) | G23: =IF($D23="","",$D23*INDEX(Assumptions!$C$25:$G$30,MATCH($C23,Assumptions!$B$25:$B$30,0),3)) | H23: =IF($D23="","",$D23*INDEX(Assumptions!$C$25:$G$30,MATCH($C23,Assumptions!$B$25:$B$30,0),4)) | I23: =IF($D23="","",$D23*INDEX(Assumptions!$C$25:$G$30,MATCH($C23,Assumptions!$B$25:$B$30,0),5)) | J23: =SUM(E23:I23)
B24: Block total | E24: =SUM(E18:E23) | F24: =SUM(F18:F23) | G24: =SUM(G18:G23) | H24: =SUM(H18:H23) | I24: =SUM(I18:I23) | J24: =SUM(J18:J23) | K24: =IFERROR(J24/$J$51,0)
B26: BLOCK 3. Transaction costs (Buy / Partner)
B27: Payment provider fees (all-in, incl. payouts & FX) | C27: GMV | D27: 250800 | E27: =IF($D27="","",$D27*INDEX(Assumptions!$C$25:$G$30,MATCH($C27,Assumptions!$B$25:$B$30,0),1)) | F27: =IF($D27="","",$D27*INDEX(Assumptions!$C$25:$G$30,MATCH($C27,Assumptions!$B$25:$B$30,0),2)) | G27: =IF($D27="","",$D27*INDEX(Assumptions!$C$25:$G$30,MATCH($C27,Assumptions!$B$25:$B$30,0),3)) | H27: =IF($D27="","",$D27*INDEX(Assumptions!$C$25:$G$30,MATCH($C27,Assumptions!$B$25:$B$30,0),4)) | I27: =IF($D27="","",$D27*INDEX(Assumptions!$C$25:$G$30,MATCH($C27,Assumptions!$B$25:$B$30,0),5)) | J27: =SUM(E27:I27) | L27: 1.9% blended of Y1 GMV $13.2M - see Task5/adr-004 (cap 2.5%, A6 p.6)
B28: SMS notifications | C28: orders | D28: 36000 | E28: =IF($D28="","",$D28*INDEX(Assumptions!$C$25:$G$30,MATCH($C28,Assumptions!$B$25:$B$30,0),1)) | F28: =IF($D28="","",$D28*INDEX(Assumptions!$C$25:$G$30,MATCH($C28,Assumptions!$B$25:$B$30,0),2)) | G28: =IF($D28="","",$D28*INDEX(Assumptions!$C$25:$G$30,MATCH($C28,Assumptions!$B$25:$B$30,0),3)) | H28: =IF($D28="","",$D28*INDEX(Assumptions!$C$25:$G$30,MATCH($C28,Assumptions!$B$25:$B$30,0),4)) | I28: =IF($D28="","",$D28*INDEX(Assumptions!$C$25:$G$30,MATCH($C28,Assumptions!$B$25:$B$30,0),5)) | J28: =SUM(E28:I28) | L28: 3 SMS/order x $0.02 (Africa's Talking NG/KE)
B29: WhatsApp messages (utility templates) | C29: orders | D29: 6000 | E29: =IF($D29="","",$D29*INDEX(Assumptions!$C$25:$G$30,MATCH($C29,Assumptions!$B$25:$B$30,0),1)) | F29: =IF($D29="","",$D29*INDEX(Assumptions!$C$25:$G$30,MATCH($C29,Assumptions!$B$25:$B$30,0),2)) | G29: =IF($D29="","",$D29*INDEX(Assumptions!$C$25:$G$30,MATCH($C29,Assumptions!$B$25:$B$30,0),3)) | H29: =IF($D29="","",$D29*INDEX(Assumptions!$C$25:$G$30,MATCH($C29,Assumptions!$B$25:$B$30,0),4)) | I29: =IF($D29="","",$D29*INDEX(Assumptions!$C$25:$G$30,MATCH($C29,Assumptions!$B$25:$B$30,0),5)) | J29: =SUM(E29:I29) | L29: ~$0.01/order seller+buyer utility msgs
B30: Logistics: partner API fees + delivery subsidy | C30: orders | D30: 90000 | E30: =IF($D30="","",$D30*INDEX(Assumptions!$C$25:$G$30,MATCH($C30,Assumptions!$B$25:$B$30,0),1)) | F30: =IF($D30="","",$D30*INDEX(Assumptions!$C$25:$G$30,MATCH($C30,Assumptions!$B$25:$B$30,0),2)) | G30: =IF($D30="","",$D30*INDEX(Assumptions!$C$25:$G$30,MATCH($C30,Assumptions!$B$25:$B$30,0),3)) | H30: =IF($D30="","",$D30*INDEX(Assumptions!$C$25:$G$30,MATCH($C30,Assumptions!$B$25:$B$30,0),4)) | I30: =IF($D30="","",$D30*INDEX(Assumptions!$C$25:$G$30,MATCH($C30,Assumptions!$B$25:$B$30,0),5)) | J30: =SUM(E30:I30) | L30: $0.15/order platform-paid on top of buyer delivery fee (Sendbox NG, Sendy KE)
B31: USSD sessions + short codes (NG, KE) | C31: orders | D31: 12000 | E31: =IF($D31="","",$D31*INDEX(Assumptions!$C$25:$G$30,MATCH($C31,Assumptions!$B$25:$B$30,0),1)) | F31: =IF($D31="","",$D31*INDEX(Assumptions!$C$25:$G$30,MATCH($C31,Assumptions!$B$25:$B$30,0),2)) | G31: =IF($D31="","",$D31*INDEX(Assumptions!$C$25:$G$30,MATCH($C31,Assumptions!$B$25:$B$30,0),3)) | H31: =IF($D31="","",$D31*INDEX(Assumptions!$C$25:$G$30,MATCH($C31,Assumptions!$B$25:$B$30,0),4)) | I31: =IF($D31="","",$D31*INDEX(Assumptions!$C$25:$G$30,MATCH($C31,Assumptions!$B$25:$B$30,0),5)) | J31: =SUM(E31:I31) | L31: Africa's Talking USSD aggregator
B32: Block total | E32: =SUM(E27:E31) | F32: =SUM(F27:F31) | G32: =SUM(G27:G31) | H32: =SUM(H27:H31) | I32: =SUM(I27:I31) | J32: =SUM(J27:J31) | K32: =IFERROR(J32/$J$51,0)
B34: BLOCK 4. Team (payroll)
B35: Development (FTE x annual rate) | C35: payroll | D35: 360000 | E35: =IF($D35="","",$D35*INDEX(Assumptions!$C$25:$G$30,MATCH($C35,Assumptions!$B$25:$B$30,0),1)) | F35: =IF($D35="","",$D35*INDEX(Assumptions!$C$25:$G$30,MATCH($C35,Assumptions!$B$25:$B$30,0),2)) | G35: =IF($D35="","",$D35*INDEX(Assumptions!$C$25:$G$30,MATCH($C35,Assumptions!$B$25:$B$30,0),3)) | H35: =IF($D35="","",$D35*INDEX(Assumptions!$C$25:$G$30,MATCH($C35,Assumptions!$B$25:$B$30,0),4)) | I35: =IF($D35="","",$D35*INDEX(Assumptions!$C$25:$G$30,MATCH($C35,Assumptions!$B$25:$B$30,0),5)) | J35: =SUM(E35:I35) | L35: 6 developers (exceeds 6-contractor cap when SRE added)
B36: DevOps / SRE | C36: payroll | D36: 144000 | E36: =IF($D36="","",$D36*INDEX(Assumptions!$C$25:$G$30,MATCH($C36,Assumptions!$B$25:$B$30,0),1)) | F36: =IF($D36="","",$D36*INDEX(Assumptions!$C$25:$G$30,MATCH($C36,Assumptions!$B$25:$B$30,0),2)) | G36: =IF($D36="","",$D36*INDEX(Assumptions!$C$25:$G$30,MATCH($C36,Assumptions!$B$25:$B$30,0),3)) | H36: =IF($D36="","",$D36*INDEX(Assumptions!$C$25:$G$30,MATCH($C36,Assumptions!$B$25:$B$30,0),4)) | I36: =IF($D36="","",$D36*INDEX(Assumptions!$C$25:$G$30,MATCH($C36,Assumptions!$B$25:$B$30,0),5)) | J36: =SUM(E36:I36) | L36: 2 platform/SRE
B37: On-call 24/7 (follow-the-sun stipend) | C37: payroll | D37: 24000 | E37: =IF($D37="","",$D37*INDEX(Assumptions!$C$25:$G$30,MATCH($C37,Assumptions!$B$25:$B$30,0),1)) | F37: =IF($D37="","",$D37*INDEX(Assumptions!$C$25:$G$30,MATCH($C37,Assumptions!$B$25:$B$30,0),2)) | G37: =IF($D37="","",$D37*INDEX(Assumptions!$C$25:$G$30,MATCH($C37,Assumptions!$B$25:$B$30,0),3)) | H37: =IF($D37="","",$D37*INDEX(Assumptions!$C$25:$G$30,MATCH($C37,Assumptions!$B$25:$B$30,0),4)) | I37: =IF($D37="","",$D37*INDEX(Assumptions!$C$25:$G$30,MATCH($C37,Assumptions!$B$25:$B$30,0),5)) | J37: =SUM(E37:I37)
B38: Architecture & management | C38: payroll | D38: 200000 | E38: =IF($D38="","",$D38*INDEX(Assumptions!$C$25:$G$30,MATCH($C38,Assumptions!$B$25:$B$30,0),1)) | F38: =IF($D38="","",$D38*INDEX(Assumptions!$C$25:$G$30,MATCH($C38,Assumptions!$B$25:$B$30,0),2)) | G38: =IF($D38="","",$D38*INDEX(Assumptions!$C$25:$G$30,MATCH($C38,Assumptions!$B$25:$B$30,0),3)) | H38: =IF($D38="","",$D38*INDEX(Assumptions!$C$25:$G$30,MATCH($C38,Assumptions!$B$25:$B$30,0),4)) | I38: =IF($D38="","",$D38*INDEX(Assumptions!$C$25:$G$30,MATCH($C38,Assumptions!$B$25:$B$30,0),5)) | J38: =SUM(E38:I38) | L38: Same as A
B39: Team growth from Y2 (+5 engineers) | C39: payroll | D39: 300000 | E39: 0 | F39: =IF($D39="","",$D39*INDEX(Assumptions!$C$25:$G$30,MATCH($C39,Assumptions!$B$25:$B$30,0),2)) | G39: =IF($D39="","",$D39*INDEX(Assumptions!$C$25:$G$30,MATCH($C39,Assumptions!$B$25:$B$30,0),3)) | H39: =IF($D39="","",$D39*INDEX(Assumptions!$C$25:$G$30,MATCH($C39,Assumptions!$B$25:$B$30,0),4)) | I39: =IF($D39="","",$D39*INDEX(Assumptions!$C$25:$G$30,MATCH($C39,Assumptions!$B$25:$B$30,0),5)) | J39: =SUM(E39:I39) | L39: Y1 = 0 (overridden)
B40: Block total | E40: =SUM(E35:E39) | F40: =SUM(F35:F39) | G40: =SUM(G35:G39) | H40: =SUM(H35:H39) | I40: =SUM(I35:I39) | J40: =SUM(J35:J39) | K40: =IFERROR(J40/$J$51,0)
B42: BLOCK 5. One-off & compliance
B43: Legal & compliance (NDPR/NDPA, POPIA, KE DPA) | C43: fixed | D43: 30000 | E43: =IF($D43="","",$D43*INDEX(Assumptions!$C$25:$G$30,MATCH($C43,Assumptions!$B$25:$B$30,0),1)) | F43: 15000 | G43: 15000 | H43: 15000 | I43: 15000 | J43: =SUM(E43:I43) | L43: Y1: DPIA, NDPC/ODPC registration, outsourced DPO; Y2+: annual NDPC audit filing
B44: Penetration test & security audit | C44: inflation | D44: 12000 | E44: =IF($D44="","",$D44*INDEX(Assumptions!$C$25:$G$30,MATCH($C44,Assumptions!$B$25:$B$30,0),1)) | F44: =IF($D44="","",$D44*INDEX(Assumptions!$C$25:$G$30,MATCH($C44,Assumptions!$B$25:$B$30,0),2)) | G44: =IF($D44="","",$D44*INDEX(Assumptions!$C$25:$G$30,MATCH($C44,Assumptions!$B$25:$B$30,0),3)) | H44: =IF($D44="","",$D44*INDEX(Assumptions!$C$25:$G$30,MATCH($C44,Assumptions!$B$25:$B$30,0),4)) | I44: =IF($D44="","",$D44*INDEX(Assumptions!$C$25:$G$30,MATCH($C44,Assumptions!$B$25:$B$30,0),5)) | J44: =SUM(E44:I44) | L44: Annual, before peak season
B45: Launch integrations & certification | C45: fixed | D45: 15000 | E45: =IF($D45="","",$D45*INDEX(Assumptions!$C$25:$G$30,MATCH($C45,Assumptions!$B$25:$B$30,0),1)) | F45: 0 | G45: 0 | H45: 0 | I45: 0 | J45: =SUM(E45:I45) | L45: One-off
...

Sheet TCO-C Microservices (CTO)
B1: Option C - CTO proposal: 40-50 microservices, Istio, Kafka, Oracle, 3 clusters, build logistics & payments
B2: 5-year TCO - Africa Delivery
B3: Inputs: 'Growth driver' and 'Base, $/yr (Year 1)'. Years 1-5 are calculated.
B5: Cost item | C5: Growth driver | D5: Base, $/yr (Year 1) | E5: Year 1 | F5: Year 2 | G5: Year 3 | H5: Year 4 | I5: Year 5 | J5: Total 5 yrs | K5: Share | L5: Comment / source
B6: BLOCK 1. Cloud infrastructure (OpEx)
B7: Compute: 3 Kubernetes clusters | C7: users | D7: 68400 | E7: =IF($D7="","",$D7*INDEX(Assumptions!$C$25:$G$30,MATCH($C7,Assumptions!$B$25:$B$30,0),1)) | F7: =IF($D7="","",$D7*INDEX(Assumptions!$C$25:$G$30,MATCH($C7,Assumptions!$B$25:$B$30,0),2)) | G7: =IF($D7="","",$D7*INDEX(Assumptions!$C$25:$G$30,MATCH($C7,Assumptions!$B$25:$B$30,0),3)) | H7: =IF($D7="","",$D7*INDEX(Assumptions!$C$25:$G$30,MATCH($C7,Assumptions!$B$25:$B$30,0),4)) | I7: =IF($D7="","",$D7*INDEX(Assumptions!$C$25:$G$30,MATCH($C7,Assumptions!$B$25:$B$30,0),5)) | J7: =SUM(E7:I7) | L7: GCP africa-south1 + AWS af-south-1 + on-prem Lagos, 6 nodes each; Istio overhead ~25%
B8: Databases: self-run Oracle + Postgres operators | C8: users | D8: 21600 | E8: =IF($D8="","",$D8*INDEX(Assumptions!$C$25:$G$30,MATCH($C8,Assumptions!$B$25:$B$30,0),1)) | F8: =IF($D8="","",$D8*INDEX(Assumptions!$C$25:$G$30,MATCH($C8,Assumptions!$B$25:$B$30,0),2)) | G8: =IF($D8="","",$D8*INDEX(Assumptions!$C$25:$G$30,MATCH($C8,Assumptions!$B$25:$B$30,0),3)) | H8: =IF($D8="","",$D8*INDEX(Assumptions!$C$25:$G$30,MATCH($C8,Assumptions!$B$25:$B$30,0),4)) | I8: =IF($D8="","",$D8*INDEX(Assumptions!$C$25:$G$30,MATCH($C8,Assumptions!$B$25:$B$30,0),5)) | J8: =SUM(E8:I8) | L8: Oracle on 2x r6i.xlarge (Data Guard) + Postgres for edge services
B9: Object storage & backups | C9: users | D9: 4800 | E9: =IF($D9="","",$D9*INDEX(Assumptions!$C$25:$G$30,MATCH($C9,Assumptions!$B$25:$B$30,0),1)) | F9: =IF($D9="","",$D9*INDEX(Assumptions!$C$25:$G$30,MATCH($C9,Assumptions!$B$25:$B$30,0),2)) | G9: =IF($D9="","",$D9*INDEX(Assumptions!$C$25:$G$30,MATCH($C9,Assumptions!$B$25:$B$30,0),3)) | H9: =IF($D9="","",$D9*INDEX(Assumptions!$C$25:$G$30,MATCH($C9,Assumptions!$B$25:$B$30,0),4)) | I9: =IF($D9="","",$D9*INDEX(Assumptions!$C$25:$G$30,MATCH($C9,Assumptions!$B$25:$B$30,0),5)) | J9: =SUM(E9:I9)
B10: CDN & cross-cloud replication egress | C10: users | D10: 18000 | E10: =IF($D10="","",$D10*INDEX(Assumptions!$C$25:$G$30,MATCH($C10,Assumptions!$B$25:$B$30,0),1)) | F10: =IF($D10="","",$D10*INDEX(Assumptions!$C$25:$G$30,MATCH($C10,Assumptions!$B$25:$B$30,0),2)) | G10: =IF($D10="","",$D10*INDEX(Assumptions!$C$25:$G$30,MATCH($C10,Assumptions!$B$25:$B$30,0),3)) | H10: =IF($D10="","",$D10*INDEX(Assumptions!$C$25:$G$30,MATCH($C10,Assumptions!$B$25:$B$30,0),4)) | I10: =IF($D10="","",$D10*INDEX(Assumptions!$C$25:$G$30,MATCH($C10,Assumptions!$B$25:$B$30,0),5)) | J10: =SUM(E10:I10) | L10: Kafka MirrorMaker + DB replication between clouds
B11: Self-hosted Kafka (3 brokers x 3 clusters) | C11: users | D11: 21600 | E11: =IF($D11="","",$D11*INDEX(Assumptions!$C$25:$G$30,MATCH($C11,Assumptions!$B$25:$B$30,0),1)) | F11: =IF($D11="","",$D11*INDEX(Assumptions!$C$25:$G$30,MATCH($C11,Assumptions!$B$25:$B$30,0),2)) | G11: =IF($D11="","",$D11*INDEX(Assumptions!$C$25:$G$30,MATCH($C11,Assumptions!$B$25:$B$30,0),3)) | H11: =IF($D11="","",$D11*INDEX(Assumptions!$C$25:$G$30,MATCH($C11,Assumptions!$B$25:$B$30,0),4)) | I11: =IF($D11="","",$D11*INDEX(Assumptions!$C$25:$G$30,MATCH($C11,Assumptions!$B$25:$B$30,0),5)) | J11: =SUM(E11:I11) | L11: A5: 'Kafka as backbone'
B12: Inter-cloud VPN / interconnect | C12: inflation | D12: 6000 | E12: =IF($D12="","",$D12*INDEX(Assumptions!$C$25:$G$30,MATCH($C12,Assumptions!$B$25:$B$30,0),1)) | F12: =IF($D12="","",$D12*INDEX(Assumptions!$C$25:$G$30,MATCH($C12,Assumptions!$B$25:$B$30,0),2)) | G12: =IF($D12="","",$D12*INDEX(Assumptions!$C$25:$G$30,MATCH($C12,Assumptions!$B$25:$B$30,0),3)) | H12: =IF($D12="","",$D12*INDEX(Assumptions!$C$25:$G$30,MATCH($C12,Assumptions!$B$25:$B$30,0),4)) | I12: =IF($D12="","",$D12*INDEX(Assumptions!$C$25:$G$30,MATCH($C12,Assumptions!$B$25:$B$30,0),5)) | J12: =SUM(E12:I12) | L12: Active-active: the 2nd region is production, not DR
B13: On-prem cluster in Lagos (colocation) | C13: inflation | D13: 30000 | E13: =IF($D13="","",$D13*INDEX(Assumptions!$C$25:$G$30,MATCH($C13,Assumptions!$B$25:$B$30,0),1)) | F13: =IF($D13="","",$D13*INDEX(Assumptions!$C$25:$G$30,MATCH($C13,Assumptions!$B$25:$B$30,0),2)) | G13: =IF($D13="","",$D13*INDEX(Assumptions!$C$25:$G$30,MATCH($C13,Assumptions!$B$25:$B$30,0),3)) | H13: =IF($D13="","",$D13*INDEX(Assumptions!$C$25:$G$30,MATCH($C13,Assumptions!$B$25:$B$30,0),4)) | I13: =IF($D13="","",$D13*INDEX(Assumptions!$C$25:$G$30,MATCH($C13,Assumptions!$B$25:$B$30,0),5)) | J13: =SUM(E13:I13) | L13: 3 leased servers, rack, power, bandwidth
B14: Cache: self-hosted Redis per cluster | C14: users | D14: 3600 | E14: =IF($D14="","",$D14*INDEX(Assumptions!$C$25:$G$30,MATCH($C14,Assumptions!$B$25:$B$30,0),1)) | F14: =IF($D14="","",$D14*INDEX(Assumptions!$C$25:$G$30,MATCH($C14,Assumptions!$B$25:$B$30,0),2)) | G14: =IF($D14="","",$D14*INDEX(Assumptions!$C$25:$G$30,MATCH($C14,Assumptions!$B$25:$B$30,0),3)) | H14: =IF($D14="","",$D14*INDEX(Assumptions!$C$25:$G$30,MATCH($C14,Assumptions!$B$25:$B$30,0),4)) | I14: =IF($D14="","",$D14*INDEX(Assumptions!$C$25:$G$30,MATCH($C14,Assumptions!$B$25:$B$30,0),5)) | J14: =SUM(E14:I14)
B15: Block total | E15: =SUM(E7:E14) | F15: =SUM(F7:F14) | G15: =SUM(G7:G14) | H15: =SUM(H7:H14) | I15: =SUM(I7:I14) | J15: =SUM(J7:J14) | K15: =IFERROR(J15/$J$51,0)
B17: BLOCK 2. Licences, SaaS & tools
B18: Observability: self-hosted full stack | C18: users | D18: 7200 | E18: =IF($D18="","",$D18*INDEX(Assumptions!$C$25:$G$30,MATCH($C18,Assumptions!$B$25:$B$30,0),1)) | F18: =IF($D18="","",$D18*INDEX(Assumptions!$C$25:$G$30,MATCH($C18,Assumptions!$B$25:$B$30,0),2)) | G18: =IF($D18="","",$D18*INDEX(Assumptions!$C$25:$G$30,MATCH($C18,Assumptions!$B$25:$B$30,0),3)) | H18: =IF($D18="","",$D18*INDEX(Assumptions!$C$25:$G$30,MATCH($C18,Assumptions!$B$25:$B$30,0),4)) | I18: =IF($D18="","",$D18*INDEX(Assumptions!$C$25:$G$30,MATCH($C18,Assumptions!$B$25:$B$30,0),5)) | J18: =SUM(E18:I18) | L18: Prometheus/Loki/Jaeger storage x3 clusters
B19: CI/CD, repo, artifacts | C19: inflation | D19: 6000 | E19: =IF($D19="","",$D19*INDEX(Assumptions!$C$25:$G$30,MATCH($C19,Assumptions!$B$25:$B$30,0),1)) | F19: =IF($D19="","",$D19*INDEX(Assumptions!$C$25:$G$30,MATCH($C19,Assumptions!$B$25:$B$30,0),2)) | G19: =IF($D19="","",$D19*INDEX(Assumptions!$C$25:$G$30,MATCH($C19,Assumptions!$B$25:$B$30,0),3)) | H19: =IF($D19="","",$D19*INDEX(Assumptions!$C$25:$G$30,MATCH($C19,Assumptions!$B$25:$B$30,0),4)) | I19: =IF($D19="","",$D19*INDEX(Assumptions!$C$25:$G$30,MATCH($C19,Assumptions!$B$25:$B$30,0),5)) | J19: =SUM(E19:I19) | L19: 40+ pipelines, GitHub + ArgoCD
B20: Security: WAF, Vault, mTLS PKI | C20: users | D20: 3600 | E20: =IF($D20="","",$D20*INDEX(Assumptions!$C$25:$G$30,MATCH($C20,Assumptions!$B$25:$B$30,0),1)) | F20: =IF($D20="","",$D20*INDEX(Assumptions!$C$25:$G$30,MATCH($C20,Assumptions!$B$25:$B$30,0),2)) | G20: =IF($D20="","",$D20*INDEX(Assumptions!$C$25:$G$30,MATCH($C20,Assumptions!$B$25:$B$30,0),3)) | H20: =IF($D20="","",$D20*INDEX(Assumptions!$C$25:$G$30,MATCH($C20,Assumptions!$B$25:$B$30,0),4)) | I20: =IF($D20="","",$D20*INDEX(Assumptions!$C$25:$G$30,MATCH($C20,Assumptions!$B$25:$B$30,0),5)) | J20: =SUM(E20:I20)
B21: WhatsApp Business API (BSP subscription) | C21: inflation | D21: 1200 | E21: =IF($D21="","",$D21*INDEX(Assumptions!$C$25:$G$30,MATCH($C21,Assumptions!$B$25:$B$30,0),1)) | F21: =IF($D21="","",$D21*INDEX(Assumptions!$C$25:$G$30,MATCH($C21,Assumptions!$B$25:$B$30,0),2)) | G21: =IF($D21="","",$D21*INDEX(Assumptions!$C$25:$G$30,MATCH($C21,Assumptions!$B$25:$B$30,0),3)) | H21: =IF($D21="","",$D21*INDEX(Assumptions!$C$25:$G$30,MATCH($C21,Assumptions!$B$25:$B$30,0),4)) | I21: =IF($D21="","",$D21*INDEX(Assumptions!$C$25:$G$30,MATCH($C21,Assumptions!$B$25:$B$30,0),5)) | J21: =SUM(E21:I21)
B22: Other SaaS | C22: inflation | D22: 2400 | E22: =IF($D22="","",$D22*INDEX(Assumptions!$C$25:$G$30,MATCH($C22,Assumptions!$B$25:$B$30,0),1)) | F22: =IF($D22="","",$D22*INDEX(Assumptions!$C$25:$G$30,MATCH($C22,Assumptions!$B$25:$B$30,0),2)) | G22: =IF($D22="","",$D22*INDEX(Assumptions!$C$25:$G$30,MATCH($C22,Assumptions!$B$25:$B$30,0),3)) | H22: =IF($D22="","",$D22*INDEX(Assumptions!$C$25:$G$30,MATCH($C22,Assumptions!$B$25:$B$30,0),4)) | I22: =IF($D22="","",$D22*INDEX(Assumptions!$C$25:$G$30,MATCH($C22,Assumptions!$B$25:$B$30,0),5)) | J22: =SUM(E22:I22)
B23: Oracle support (22%/yr of licences) | C23: inflation | D23: 41800 | E23: =IF($D23="","",$D23*INDEX(Assumptions!$C$25:$G$30,MATCH($C23,Assumptions!$B$25:$B$30,0),1)) | F23: =IF($D23="","",$D23*INDEX(Assumptions!$C$25:$G$30,MATCH($C23,Assumptions!$B$25:$B$30,0),2)) | G23: =IF($D23="","",$D23*INDEX(Assumptions!$C$25:$G$30,MATCH($C23,Assumptions!$B$25:$B$30,0),3)) | H23: =IF($D23="","",$D23*INDEX(Assumptions!$C$25:$G$30,MATCH($C23,Assumptions!$B$25:$B$30,0),4)) | I23: =IF($D23="","",$D23*INDEX(Assumptions!$C$25:$G$30,MATCH($C23,Assumptions!$B$25:$B$30,0),5)) | J23: =SUM(E23:I23) | L23: CFO A6 p.7: per-core licences need justification
B24: Block total | E24: =SUM(E18:E23) | F24: =SUM(F18:F23) | G24: =SUM(G18:G23) | H24: =SUM(H18:H23) | I24: =SUM(I18:I23) | J24: =SUM(J18:J23) | K24: =IFERROR(J24/$J$51,0)
B26: BLOCK 3. Transaction costs (Buy / Partner)
B27: Payment provider fees (direct integrations) | C27: GMV | D27: 224400 | E27: =IF($D27="","",$D27*INDEX(Assumptions!$C$25:$G$30,MATCH($C27,Assumptions!$B$25:$B$30,0),1)) | F27: =IF($D27="","",$D27*INDEX(Assumptions!$C$25:$G$30,MATCH($C27,Assumptions!$B$25:$B$30,0),2)) | G27: =IF($D27="","",$D27*INDEX(Assumptions!$C$25:$G$30,MATCH($C27,Assumptions!$B$25:$B$30,0),3)) | H27: =IF($D27="","",$D27*INDEX(Assumptions!$C$25:$G$30,MATCH($C27,Assumptions!$B$25:$B$30,0),4)) | I27: =IF($D27="","",$D27*INDEX(Assumptions!$C$25:$G$30,MATCH($C27,Assumptions!$B$25:$B$30,0),5)) | J27: =SUM(E27:I27) | L27: 1.7%: CTO claim of -0.2pp via direct M-Pesa/Flutterwave
B28: SMS notifications | C28: orders | D28: 36000 | E28: =IF($D28="","",$D28*INDEX(Assumptions!$C$25:$G$30,MATCH($C28,Assumptions!$B$25:$B$30,0),1)) | F28: =IF($D28="","",$D28*INDEX(Assumptions!$C$25:$G$30,MATCH($C28,Assumptions!$B$25:$B$30,0),2)) | G28: =IF($D28="","",$D28*INDEX(Assumptions!$C$25:$G$30,MATCH($C28,Assumptions!$B$25:$B$30,0),3)) | H28: =IF($D28="","",$D28*INDEX(Assumptions!$C$25:$G$30,MATCH($C28,Assumptions!$B$25:$B$30,0),4)) | I28: =IF($D28="","",$D28*INDEX(Assumptions!$C$25:$G$30,MATCH($C28,Assumptions!$B$25:$B$30,0),5)) | J28: =SUM(E28:I28) | L28: 3 SMS/order x $0.02 (Africa's Talking NG/KE)
B29: WhatsApp messages (utility templates) | C29: orders | D29: 6000 | E29: =IF($D29="","",$D29*INDEX(Assumptions!$C$25:$G$30,MATCH($C29,Assumptions!$B$25:$B$30,0),1)) | F29: =IF($D29="","",$D29*INDEX(Assumptions!$C$25:$G$30,MATCH($C29,Assumptions!$B$25:$B$30,0),2)) | G29: =IF($D29="","",$D29*INDEX(Assumptions!$C$25:$G$30,MATCH($C29,Assumptions!$B$25:$B$30,0),3)) | H29: =IF($D29="","",$D29*INDEX(Assumptions!$C$25:$G$30,MATCH($C29,Assumptions!$B$25:$B$30,0),4)) | I29: =IF($D29="","",$D29*INDEX(Assumptions!$C$25:$G$30,MATCH($C29,Assumptions!$B$25:$B$30,0),5)) | J29: =SUM(E29:I29) | L29: ~$0.01/order seller+buyer utility msgs
B30: Logistics: own engine (fees -30% from Y2) | C30: orders | D30: 63000 | E30: 90000 | F30: =IF($D30="","",$D30*INDEX(Assumptions!$C$25:$G$30,MATCH($C30,Assumptions!$B$25:$B$30,0),2)) | G30: =IF($D30="","",$D30*INDEX(Assumptions!$C$25:$G$30,MATCH($C30,Assumptions!$B$25:$B$30,0),3)) | H30: =IF($D30="","",$D30*INDEX(Assumptions!$C$25:$G$30,MATCH($C30,Assumptions!$B$25:$B$30,0),4)) | I30: =IF($D30="","",$D30*INDEX(Assumptions!$C$25:$G$30,MATCH($C30,Assumptions!$B$25:$B$30,0),5)) | J30: =SUM(E30:I30) | L30: Y1 = partner fees $90k (engine live only ~Apr-2027)
B31: USSD sessions + short codes (NG, KE) | C31: orders | D31: 12000 | E31: =IF($D31="","",$D31*INDEX(Assumptions!$C$25:$G$30,MATCH($C31,Assumptions!$B$25:$B$30,0),1)) | F31: =IF($D31="","",$D31*INDEX(Assumptions!$C$25:$G$30,MATCH($C31,Assumptions!$B$25:$B$30,0),2)) | G31: =IF($D31="","",$D31*INDEX(Assumptions!$C$25:$G$30,MATCH($C31,Assumptions!$B$25:$B$30,0),3)) | H31: =IF($D31="","",$D31*INDEX(Assumptions!$C$25:$G$30,MATCH($C31,Assumptions!$B$25:$B$30,0),4)) | I31: =IF($D31="","",$D31*INDEX(Assumptions!$C$25:$G$30,MATCH($C31,Assumptions!$B$25:$B$30,0),5)) | J31: =SUM(E31:I31) | L31: Africa's Talking USSD aggregator
B32: Block total | E32: =SUM(E27:E31) | F32: =SUM(F27:F31) | G32: =SUM(G27:G31) | H32: =SUM(H27:H31) | I32: =SUM(I27:I31) | J32: =SUM(J27:J31) | K32: =IFERROR(J32/$J$51,0)
B34: BLOCK 4. Team (payroll)
B35: Development (FTE x annual rate) | C35: payroll | D35: 600000 | E35: =IF($D35="","",$D35*INDEX(Assumptions!$C$25:$G$30,MATCH($C35,Assumptions!$B$25:$B$30,0),1)) | F35: =IF($D35="","",$D35*INDEX(Assumptions!$C$25:$G$30,MATCH($C35,Assumptions!$B$25:$B$30,0),2)) | G35: =IF($D35="","",$D35*INDEX(Assumptions!$C$25:$G$30,MATCH($C35,Assumptions!$B$25:$B$30,0),3)) | H35: =IF($D35="","",$D35*INDEX(Assumptions!$C$25:$G$30,MATCH($C35,Assumptions!$B$25:$B$30,0),4)) | I35: =IF($D35="","",$D35*INDEX(Assumptions!$C$25:$G$30,MATCH($C35,Assumptions!$B$25:$B$30,0),5)) | J35: =SUM(E35:I35) | L35: 10 Go devs incl. 4-person logistics engine team (CTO estimate: 6 mo x 4 eng)
B36: Platform / SRE + Oracle DBA | C36: payroll | D36: 306000 | E36: =IF($D36="","",$D36*INDEX(Assumptions!$C$25:$G$30,MATCH($C36,Assumptions!$B$25:$B$30,0),1)) | F36: =IF($D36="","",$D36*INDEX(Assumptions!$C$25:$G$30,MATCH($C36,Assumptions!$B$25:$B$30,0),2)) | G36: =IF($D36="","",$D36*INDEX(Assumptions!$C$25:$G$30,MATCH($C36,Assumptions!$B$25:$B$30,0),3)) | H36: =IF($D36="","",$D36*INDEX(Assumptions!$C$25:$G$30,MATCH($C36,Assumptions!$B$25:$B$30,0),4)) | I36: =IF($D36="","",$D36*INDEX(Assumptions!$C$25:$G$30,MATCH($C36,Assumptions!$B$25:$B$30,0),5)) | J36: =SUM(E36:I36) | L36: 3 SRE x $72k (K8s x3, Istio, Kafka) + DBA $90k
B37: On-call 24/7 | C37: payroll | D37: 36000 | E37: =IF($D37="","",$D37*INDEX(Assumptions!$C$25:$G$30,MATCH($C37,Assumptions!$B$25:$B$30,0),1)) | F37: =IF($D37="","",$D37*INDEX(Assumptions!$C$25:$G$30,MATCH($C37,Assumptions!$B$25:$B$30,0),2)) | G37: =IF($D37="","",$D37*INDEX(Assumptions!$C$25:$G$30,MATCH($C37,Assumptions!$B$25:$B$30,0),3)) | H37: =IF($D37="","",$D37*INDEX(Assumptions!$C$25:$G$30,MATCH($C37,Assumptions!$B$25:$B$30,0),4)) | I37: =IF($D37="","",$D37*INDEX(Assumptions!$C$25:$G$30,MATCH($C37,Assumptions!$B$25:$B$30,0),5)) | J37: =SUM(E37:I37)
B38: Architecture & management | C38: payroll | D38: 200000 | E38: =IF($D38="","",$D38*INDEX(Assumptions!$C$25:$G$30,MATCH($C38,Assumptions!$B$25:$B$30,0),1)) | F38: =IF($D38="","",$D38*INDEX(Assumptions!$C$25:$G$30,MATCH($C38,Assumptions!$B$25:$B$30,0),2)) | G38: =IF($D38="","",$D38*INDEX(Assumptions!$C$25:$G$30,MATCH($C38,Assumptions!$B$25:$B$30,0),3)) | H38: =IF($D38="","",$D38*INDEX(Assumptions!$C$25:$G$30,MATCH($C38,Assumptions!$B$25:$B$30,0),4)) | I38: =IF($D38="","",$D38*INDEX(Assumptions!$C$25:$G$30,MATCH($C38,Assumptions!$B$25:$B$30,0),5)) | J38: =SUM(E38:I38) | L38: Same as A
B39: Team growth from Y2 (+6 engineers) | C39: payroll | D39: 360000 | E39: 0 | F39: =IF($D39="","",$D39*INDEX(Assumptions!$C$25:$G$30,MATCH($C39,Assumptions!$B$25:$B$30,0),2)) | G39: =IF($D39="","",$D39*INDEX(Assumptions!$C$25:$G$30,MATCH($C39,Assumptions!$B$25:$B$30,0),3)) | H39: =IF($D39="","",$D39*INDEX(Assumptions!$C$25:$G$30,MATCH($C39,Assumptions!$B$25:$B$30,0),4)) | I39: =IF($D39="","",$D39*INDEX(Assumptions!$C$25:$G$30,MATCH($C39,Assumptions!$B$25:$B$30,0),5)) | J39: =SUM(E39:I39) | L39: Y1 = 0 (overridden)
B40: Block total | E40: =SUM(E35:E39) | F40: =SUM(F35:F39) | G40: =SUM(G35:G39) | H40: =SUM(H35:H39) | I40: =SUM(I35:I39) | J40: =SUM(J35:J39) | K40: =IFERROR(J40/$J$51,0)
B42: BLOCK 5. One-off & compliance
B43: Legal & compliance (NDPR/NDPA, POPIA, KE DPA) | C43: fixed | D43: 30000 | E43: =IF($D43="","",$D43*INDEX(Assumptions!$C$25:$G$30,MATCH($C43,Assumptions!$B$25:$B$30,0),1)) | F43: 15000 | G43: 15000 | H43: 15000 | I43: 15000 | J43: =SUM(E43:I43) | L43: Y1: DPIA, NDPC/ODPC registration, outsourced DPO; Y2+: annual NDPC audit filing
B44: Penetration test & security audit | C44: inflation | D44: 12000 | E44: =IF($D44="","",$D44*INDEX(Assumptions!$C$25:$G$30,MATCH($C44,Assumptions!$B$25:$B$30,0),1)) | F44: =IF($D44="","",$D44*INDEX(Assumptions!$C$25:$G$30,MATCH($C44,Assumptions!$B$25:$B$30,0),2)) | G44: =IF($D44="","",$D44*INDEX(Assumptions!$C$25:$G$30,MATCH($C44,Assumptions!$B$25:$B$30,0),3)) | H44: =IF($D44="","",$D44*INDEX(Assumptions!$C$25:$G$30,MATCH($C44,Assumptions!$B$25:$B$30,0),4)) | I44: =IF($D44="","",$D44*INDEX(Assumptions!$C$25:$G$30,MATCH($C44,Assumptions!$B$25:$B$30,0),5)) | J44: =SUM(E44:I44) | L44: Annual, before peak season
B45: Launch integrations & certification | C45: fixed | D45: 10000 | E45: =IF($D45="","",$D45*INDEX(Assumptions!$C$25:$G$30,MATCH($C45,Assumptions!$B$25:$B$30,0),1)) | F45: 0 | G45: 0 | H45: 0 | I45: 0 | J45: =SUM(E45:I45) | L45: One-off
...
